<?xml version="1.0"?>
<robot xmlns:xacro="http://www.ros.org/wiki/xacro">
    
    <xacro:include filename="inertial_macros.xacro" />
    
    <material name="white">
        <color rgba="1 1 1 1"/>
    </material>

    <material name="orange">
        <color rgba="1 0.3 0.1 1"/>
    </material>

    <material name="blue">
        <color rgba="0.2 0.2 1 1"/>
    </material>

    <material name="black">
        <color rgba="0 0 0 1"/>
    </material>

    <!-- ... all our links and joints will go in here ... -->
    <link name="base_link">
    </link>

    <joint name="chassis_joint" type="fixed">
        <parent link="base_link"/>
        <child link="chassis"/>
        <origin xyz="0 0 0"/>
    </joint>

    <link name="chassis">
        <visual>
            <origin xyz="0.055 0 0.0185" rpy="0 0 0"/>
            <geometry>
                <box size="0.25 0.16 0.037"/>
            </geometry>
            <material name="white"/>
        </visual>
        <collision>
            <origin xyz="0.125 0 0.0185" rpy="0 0 0"/>
            <geometry>
                <box size="0.25 0.16 0.037"/>
            </geometry>
        </collision>
        <xacro:inertial_box mass="0.5" x="0.25" y="0.16" z="0.037">
            <origin xyz="0.125 0.0 0.037" rpy="0 0 0"/>
        </xacro:inertial_box>

    </link>
    <gazebo reference="chassis">
        <material>Gazebo/White</material>
    </gazebo>

    <!-- LEFT WHEEL -->

    <joint name="left_wheel_joint" type="continuous">
        <parent link="base_link"/>
        <child link="left_wheel"/>
        <origin xyz="0 0.08 0" rpy="-${pi/2} 0 0"/>
        <!-- the left wheel rotates around the z axis -->
        <axis xyz="0 0 1"/>
    </joint>

    <link name="left_wheel">
        <visual>
            <geometry>
                <cylinder length="0.025" radius="0.037" />
            </geometry>
            <material name="blue"/>
        </visual>
        <collision>
            <geometry>
                <cylinder length="0.025" radius="0.037" />
            </geometry>
        </collision>
        <xacro:inertial_cylinder mass="0.1" length="0.25" radius="0.037">
            <origin xyz="0 0 0" rpy="0 0 0"/>
        </xacro:inertial_cylinder>
    </link>
    <gazebo reference="left_wheel">
        <material>Gazebo/Yellow</material>
    </gazebo>

    <!-- RIGHT WHEEL -->

    <joint name="right_wheel_joint" type="continuous">
        <parent link="base_link"/>
        <child link="right_wheel"/>
        <origin xyz="0 -0.08 0" rpy="${pi/2} 0 0"/>
        <axis xyz="0 0 -1"/>
    </joint>

    <link name="right_wheel">
        <visual>
            <geometry>
                <cylinder length="0.025" radius="0.037" />
            </geometry>
            <material name="blue"/>
        </visual>
        <collision>
            <geometry>
                <cylinder length="0.025" radius="0.037" />
            </geometry>
        </collision>
        <xacro:inertial_cylinder mass="0.1" length="0.25" radius="0.037">
            <origin xyz="0 0 0" rpy="0 0 0"/>
        </xacro:inertial_cylinder>
    </link>
    <gazebo reference="right_wheel">
        <material>Gazebo/Yellow</material>
    </gazebo>

<!-- caster wheel shaft -->

<joint name="caster_wheel_shaft_joint" type="fixed">
        <parent link="chassis"/>
        <child link="caster_wheel_shaft"/>
        <origin xyz="0.175 0 -0.016" rpy="0 0 0"/>
        <axis xyz="0 0 -1"/>
    </joint>

    <link name="caster_wheel_shaft">
        <visual>
            <geometry>
                <cylinder length="0.032" radius="0.005" />
            </geometry>
            <material name="orange"/>
        </visual>
        <collision>
            <geometry>
                <cylinder length="0.032" radius="0.005" />
            </geometry>
        </collision>
    </link>

    <!-- CASTER WHEEL -->

    <joint name="caster_wheel_joint" type="fixed">
        <parent link="caster_wheel_shaft"/>
        <child link="caster_wheel"/>
        <origin xyz="0 0 -0.016" rpy="0 0 0"/>
    </joint>

    <link name="caster_wheel">
        <visual>
            <geometry>
                <sphere radius="0.005" />
            </geometry>
            <material name="blue"/>
        </visual>
        <collision>
            <geometry>
                <sphere radius="0.005" />
            </geometry>
        </collision>
    </link>
    <gazebo reference="caster_wheel">
        <material>Gazebo/Black</material>
        <!-- Very low friction for the caster wheel -->
        <mu1 value="0.001"/> 
        <mu2 value="0.001"/>
    </gazebo>

</robot>